[2025-08-29T14:55:38.388+0000] {taskinstance.py:1083} INFO - Dependencies all met for <TaskInstance: airbyte_dynamic_connection.trigger_airbyte_sync manual__2025-08-29T14:55:23+00:00 [queued]>
[2025-08-29T14:55:38.392+0000] {taskinstance.py:1083} INFO - Dependencies all met for <TaskInstance: airbyte_dynamic_connection.trigger_airbyte_sync manual__2025-08-29T14:55:23+00:00 [queued]>
[2025-08-29T14:55:38.393+0000] {taskinstance.py:1279} INFO - 
--------------------------------------------------------------------------------
[2025-08-29T14:55:38.393+0000] {taskinstance.py:1280} INFO - Starting attempt 1 of 1
[2025-08-29T14:55:38.393+0000] {taskinstance.py:1281} INFO - 
--------------------------------------------------------------------------------
[2025-08-29T14:55:38.398+0000] {taskinstance.py:1300} INFO - Executing <Task(AirbyteTriggerSyncOperator): trigger_airbyte_sync> on 2025-08-29 14:55:23+00:00
[2025-08-29T14:55:38.400+0000] {standard_task_runner.py:55} INFO - Started process 22626 to run task
[2025-08-29T14:55:38.402+0000] {standard_task_runner.py:82} INFO - Running: ['***', 'tasks', 'run', 'airbyte_dynamic_connection', 'trigger_airbyte_sync', 'manual__2025-08-29T14:55:23+00:00', '--job-id', '160', '--raw', '--subdir', 'DAGS_FOLDER/dynamic-airbyte-with-***.py', '--cfg-path', '/tmp/tmpl6rprh0i']
[2025-08-29T14:55:38.402+0000] {standard_task_runner.py:83} INFO - Job 160: Subtask trigger_airbyte_sync
[2025-08-29T14:55:38.434+0000] {task_command.py:388} INFO - Running <TaskInstance: airbyte_dynamic_connection.trigger_airbyte_sync manual__2025-08-29T14:55:23+00:00 [running]> on host 966b32814b47
[2025-08-29T14:55:38.468+0000] {taskinstance.py:1509} INFO - Exporting the following env vars:
AIRFLOW_CTX_DAG_OWNER=***
AIRFLOW_CTX_DAG_ID=airbyte_dynamic_connection
AIRFLOW_CTX_TASK_ID=trigger_airbyte_sync
AIRFLOW_CTX_EXECUTION_DATE=2025-08-29T14:55:23+00:00
AIRFLOW_CTX_TRY_NUMBER=1
AIRFLOW_CTX_DAG_RUN_ID=manual__2025-08-29T14:55:23+00:00
[2025-08-29T14:55:38.471+0000] {base.py:73} INFO - Using connection ID 'test-dynamic-airbyte-with-***' for task execution.
[2025-08-29T14:55:38.504+0000] {http.py:163} ERROR - HTTP error: Conflict
[2025-08-29T14:55:38.504+0000] {http.py:164} ERROR - {"message":"A sync is already running for: eab0da25-af63-4bc2-97cb-f140559e3b39","exceptionClassName":"io.airbyte.commons.server.errors.ValueConflictKnownException","exceptionStack":[],"rootCauseExceptionStack":[]}
[2025-08-29T14:55:38.510+0000] {taskinstance.py:1768} ERROR - Task failed with exception
Traceback (most recent call last):
  File "/home/airflow/.local/lib/python3.7/site-packages/airflow/providers/http/hooks/http.py", line 161, in check_response
    response.raise_for_status()
  File "/home/airflow/.local/lib/python3.7/site-packages/requests/models.py", line 1021, in raise_for_status
    raise HTTPError(http_error_msg, response=self)
requests.exceptions.HTTPError: 409 Client Error: Conflict for url: http://host.docker.internal:8001/api/v1/connections/sync

During handling of the above exception, another exception occurred:

Traceback (most recent call last):
  File "/home/airflow/.local/lib/python3.7/site-packages/airflow/providers/airbyte/operators/airbyte.py", line 74, in execute
    job_object = self.hook.submit_sync_connection(connection_id=self.connection_id)
  File "/home/airflow/.local/lib/python3.7/site-packages/airflow/providers/airbyte/hooks/airbyte.py", line 95, in submit_sync_connection
    headers={"accept": "application/json"},
  File "/home/airflow/.local/lib/python3.7/site-packages/airflow/providers/http/hooks/http.py", line 151, in run
    return self.run_and_check(session, prepped_request, extra_options)
  File "/home/airflow/.local/lib/python3.7/site-packages/airflow/providers/http/hooks/http.py", line 204, in run_and_check
    self.check_response(response)
  File "/home/airflow/.local/lib/python3.7/site-packages/airflow/providers/http/hooks/http.py", line 165, in check_response
    raise AirflowException(str(response.status_code) + ":" + response.reason)
airflow.exceptions.AirflowException: 409:Conflict
[2025-08-29T14:55:38.513+0000] {taskinstance.py:1323} INFO - Marking task as FAILED. dag_id=airbyte_dynamic_connection, task_id=trigger_airbyte_sync, execution_date=20250829T145523, start_date=20250829T145538, end_date=20250829T145538
[2025-08-29T14:55:38.518+0000] {standard_task_runner.py:105} ERROR - Failed to execute job 160 for task trigger_airbyte_sync (409:Conflict; 22626)
[2025-08-29T14:55:38.541+0000] {local_task_job.py:208} INFO - Task exited with return code 1
[2025-08-29T14:55:38.549+0000] {taskinstance.py:2578} INFO - 0 downstream tasks scheduled from follow-on schedule check
