{"timestamp":"2025-10-07T14:15:03.546318","level":"info","event":"DAG bundles loaded: dags-folder, example_dags","logger":"airflow.dag_processing.bundles.manager.DagBundlesManager"}
{"timestamp":"2025-10-07T14:15:03.546894","level":"info","event":"Filling up the DagBag from /opt/airflow/dags/airbyte-and-dbt-with-airflow.py","logger":"airflow.models.dagbag.DagBag"}
{"timestamp":"2025-10-07T14:15:03.564945","level":"info","event":"Trying to parse the dbt project using dbt ls cache cosmos_cache__airbyte_dynamic_connection__dbt_dynamic_alias...","logger":"cosmos.dbt.graph"}
{"timestamp":"2025-10-07T14:15:03.611075","level":"info","event":"Cosmos performance: time to calculate cache identifier cosmos_cache__airbyte_dynamic_connection__dbt_dynamic_alias for current version: 0.03483933303505182","logger":"cosmos.cache"}
{"timestamp":"2025-10-07T14:15:03.611231","level":"info","event":"Cosmos performance [5db252634e93|136]: The cache size for cosmos_cache__airbyte_dynamic_connection__dbt_dynamic_alias is 4058","logger":"cosmos.dbt.graph"}
{"timestamp":"2025-10-07T14:15:03.611604","level":"info","event":"Cosmos performance: Cache hit for cosmos_cache__airbyte_dynamic_connection__dbt_dynamic_alias - 7f6c90e7b7fbd54d95119723ba858828,d41d8cd98f00b204e9800998ecf8427e","logger":"cosmos.dbt.graph"}
{"timestamp":"2025-10-07T14:15:03.612208","level":"info","event":"Total nodes: 5","logger":"cosmos.dbt.graph"}
{"timestamp":"2025-10-07T14:15:03.612283","level":"info","event":"Total filtered nodes: 5","logger":"cosmos.dbt.graph"}
{"timestamp":"2025-10-07T14:15:03.612386","level":"info","event":"Cosmos performance (airbyte_dynamic_connection__dbt_dynamic_alias) -  [5db252634e93|136]: It took 0.0475s to parse the dbt project for DAG using LoadMode.DBT_LS_CACHE","logger":"cosmos.converter"}
{"timestamp":"2025-10-07T14:15:03.612928","level":"info","event":"Project /opt/airflow/dbt/my_project_dbt does not have {'dependencies.yml', 'packages.yml'}","logger":"cosmos.dbt.project"}
{"timestamp":"2025-10-07T14:15:03.613919","level":"info","event":"Project /opt/airflow/dbt/my_project_dbt does not have {'dependencies.yml', 'packages.yml'}","logger":"cosmos.dbt.project"}
{"timestamp":"2025-10-07T14:15:03.614747","level":"info","event":"Project /opt/airflow/dbt/my_project_dbt does not have {'dependencies.yml', 'packages.yml'}","logger":"cosmos.dbt.project"}
{"timestamp":"2025-10-07T14:15:03.615354","level":"info","event":"Project /opt/airflow/dbt/my_project_dbt does not have {'dependencies.yml', 'packages.yml'}","logger":"cosmos.dbt.project"}
{"timestamp":"2025-10-07T14:15:03.615990","level":"info","event":"Project /opt/airflow/dbt/my_project_dbt does not have {'dependencies.yml', 'packages.yml'}","logger":"cosmos.dbt.project"}
{"timestamp":"2025-10-07T14:15:03.616578","level":"info","event":"Project /opt/airflow/dbt/my_project_dbt does not have {'dependencies.yml', 'packages.yml'}","logger":"cosmos.dbt.project"}
{"timestamp":"2025-10-07T14:15:03.617589","level":"info","event":"Cosmos performance (airbyte_dynamic_connection__dbt_dynamic_alias) - [5db252634e93|136]: It took 0.00524s to build the Airflow DAG.","logger":"cosmos.converter"}
{"timestamp":"2025-10-07T14:15:03.618238","level":"warning","event":"/home/airflow/.local/lib/python3.12/site-packages/pydantic/main.py:463: UserWarning: Pydantic serializer warnings:\n  PydanticSerializationUnexpectedValue(Expected `str` - serialized value may not be as expected [input_value={'version': '7f6c90e7b7fb...d': 'dbt_dynamic_alias'}, input_type=dict])\n  return self.__pydantic_serializer__.to_python(\n","logger":"py.warnings"}
{"timestamp":"2025-10-07T14:15:03.643214Z","level":"info","event":"Task instance is in running state","chan":"stdout","logger":"task"}
{"timestamp":"2025-10-07T14:15:03.643338Z","level":"info","event":" Previous state of the Task instance: TaskInstanceState.QUEUED","chan":"stdout","logger":"task"}
{"timestamp":"2025-10-07T14:15:03.644465Z","level":"info","event":"Current task name:create_destination","chan":"stdout","logger":"task"}
{"timestamp":"2025-10-07T14:15:03.644545Z","level":"info","event":"Dag name:airbyte_dynamic_connection","chan":"stdout","logger":"task"}
{"timestamp":"2025-10-07T14:15:03.653490","level":"error","event":"Task failed with exception","logger":"task","error_detail":[{"exc_type":"ConnectionError","exc_value":"HTTPConnectionPool(host='host.docker.internal', port=8001): Max retries exceeded with url: /api/v1/destinations/create (Caused by NewConnectionError('<urllib3.connection.HTTPConnection object at 0xffff86db3c20>: Failed to establish a new connection: [Errno 101] Network is unreachable'))","exc_notes":[],"syntax_error":null,"is_cause":false,"frames":[{"filename":"/home/airflow/.local/lib/python3.12/site-packages/airflow/sdk/execution_time/task_runner.py","lineno":918,"name":"run"},{"filename":"/home/airflow/.local/lib/python3.12/site-packages/airflow/sdk/execution_time/task_runner.py","lineno":1213,"name":"_execute_task"},{"filename":"/home/airflow/.local/lib/python3.12/site-packages/airflow/sdk/bases/operator.py","lineno":397,"name":"wrapper"},{"filename":"/home/airflow/.local/lib/python3.12/site-packages/airflow/providers/standard/operators/python.py","lineno":217,"name":"execute"},{"filename":"/home/airflow/.local/lib/python3.12/site-packages/airflow/providers/standard/operators/python.py","lineno":240,"name":"execute_callable"},{"filename":"/home/airflow/.local/lib/python3.12/site-packages/airflow/sdk/execution_time/callback_runner.py","lineno":81,"name":"run"},{"filename":"/opt/airflow/dags/airbyte-and-dbt-with-airflow.py","lineno":96,"name":"create_destination"},{"filename":"/home/airflow/.local/lib/python3.12/site-packages/requests/api.py","lineno":115,"name":"post"},{"filename":"/home/airflow/.local/lib/python3.12/site-packages/requests/api.py","lineno":59,"name":"request"},{"filename":"/home/airflow/.local/lib/python3.12/site-packages/requests/sessions.py","lineno":589,"name":"request"},{"filename":"/home/airflow/.local/lib/python3.12/site-packages/requests/sessions.py","lineno":703,"name":"send"},{"filename":"/home/airflow/.local/lib/python3.12/site-packages/requests/adapters.py","lineno":700,"name":"send"}],"is_group":false,"exceptions":[]},{"exc_type":"MaxRetryError","exc_value":"HTTPConnectionPool(host='host.docker.internal', port=8001): Max retries exceeded with url: /api/v1/destinations/create (Caused by NewConnectionError('<urllib3.connection.HTTPConnection object at 0xffff86db3c20>: Failed to establish a new connection: [Errno 101] Network is unreachable'))","exc_notes":[],"syntax_error":null,"is_cause":false,"frames":[{"filename":"/home/airflow/.local/lib/python3.12/site-packages/requests/adapters.py","lineno":667,"name":"send"},{"filename":"/home/airflow/.local/lib/python3.12/site-packages/urllib3/connectionpool.py","lineno":841,"name":"urlopen"},{"filename":"/home/airflow/.local/lib/python3.12/site-packages/urllib3/util/retry.py","lineno":519,"name":"increment"}],"is_group":false,"exceptions":[]},{"exc_type":"NewConnectionError","exc_value":"<urllib3.connection.HTTPConnection object at 0xffff86db3c20>: Failed to establish a new connection: [Errno 101] Network is unreachable","exc_notes":[],"syntax_error":null,"is_cause":true,"frames":[{"filename":"/home/airflow/.local/lib/python3.12/site-packages/urllib3/connectionpool.py","lineno":787,"name":"urlopen"},{"filename":"/home/airflow/.local/lib/python3.12/site-packages/urllib3/connectionpool.py","lineno":493,"name":"_make_request"},{"filename":"/home/airflow/.local/lib/python3.12/site-packages/urllib3/connection.py","lineno":494,"name":"request"},{"filename":"/usr/local/lib/python3.12/http/client.py","lineno":1333,"name":"endheaders"},{"filename":"/usr/local/lib/python3.12/http/client.py","lineno":1093,"name":"_send_output"},{"filename":"/usr/local/lib/python3.12/http/client.py","lineno":1037,"name":"send"},{"filename":"/home/airflow/.local/lib/python3.12/site-packages/urllib3/connection.py","lineno":325,"name":"connect"},{"filename":"/home/airflow/.local/lib/python3.12/site-packages/urllib3/connection.py","lineno":213,"name":"_new_conn"}],"is_group":false,"exceptions":[]},{"exc_type":"OSError","exc_value":"[Errno 101] Network is unreachable","exc_notes":[],"syntax_error":null,"is_cause":true,"frames":[{"filename":"/home/airflow/.local/lib/python3.12/site-packages/urllib3/connection.py","lineno":198,"name":"_new_conn"},{"filename":"/home/airflow/.local/lib/python3.12/site-packages/urllib3/util/connection.py","lineno":85,"name":"create_connection"},{"filename":"/home/airflow/.local/lib/python3.12/site-packages/urllib3/util/connection.py","lineno":73,"name":"create_connection"}],"is_group":false,"exceptions":[]}]}
{"timestamp":"2025-10-07T14:15:03.656168Z","level":"info","event":"Task instance in failure state","chan":"stdout","logger":"task"}
{"timestamp":"2025-10-07T14:15:03.657880Z","level":"info","event":"Task start","chan":"stdout","logger":"task"}
{"timestamp":"2025-10-07T14:15:03.658157Z","level":"info","event":"Task:<Task(PythonOperator): create_destination>","chan":"stdout","logger":"task"}
{"timestamp":"2025-10-07T14:15:03.658477Z","level":"info","event":"Failure caused by HTTPConnectionPool(host='host.docker.internal', port=8001): Max retries exceeded with url: /api/v1/destinations/create (Caused by NewConnectionError('<urllib3.connection.HTTPConnection object at 0xffff86db3c20>: Failed to establish a new connection: [Errno 101] Network is unreachable'))","chan":"stdout","logger":"task"}
