[2025-08-28T11:36:25.918+0000] {taskinstance.py:1083} INFO - Dependencies all met for <TaskInstance: airbyte_dynamic_connection.wait_for_airbyte_idle manual__2025-08-28T11:36:24.099368+00:00 [queued]>
[2025-08-28T11:36:25.922+0000] {taskinstance.py:1083} INFO - Dependencies all met for <TaskInstance: airbyte_dynamic_connection.wait_for_airbyte_idle manual__2025-08-28T11:36:24.099368+00:00 [queued]>
[2025-08-28T11:36:25.922+0000] {taskinstance.py:1279} INFO - 
--------------------------------------------------------------------------------
[2025-08-28T11:36:25.922+0000] {taskinstance.py:1280} INFO - Starting attempt 1 of 1
[2025-08-28T11:36:25.922+0000] {taskinstance.py:1281} INFO - 
--------------------------------------------------------------------------------
[2025-08-28T11:36:25.928+0000] {taskinstance.py:1300} INFO - Executing <Task(AirbyteJobSensor): wait_for_airbyte_idle> on 2025-08-28 11:36:24.099368+00:00
[2025-08-28T11:36:25.930+0000] {standard_task_runner.py:55} INFO - Started process 1274 to run task
[2025-08-28T11:36:25.932+0000] {standard_task_runner.py:82} INFO - Running: ['***', 'tasks', 'run', 'airbyte_dynamic_connection', 'wait_for_airbyte_idle', 'manual__2025-08-28T11:36:24.099368+00:00', '--job-id', '48', '--raw', '--subdir', 'DAGS_FOLDER/dynamic-airbyte-with-***.py', '--cfg-path', '/tmp/tmp_zekzdfz']
[2025-08-28T11:36:25.932+0000] {standard_task_runner.py:83} INFO - Job 48: Subtask wait_for_airbyte_idle
[2025-08-28T11:36:25.962+0000] {task_command.py:388} INFO - Running <TaskInstance: airbyte_dynamic_connection.wait_for_airbyte_idle manual__2025-08-28T11:36:24.099368+00:00 [running]> on host 966b32814b47
[2025-08-28T11:36:25.995+0000] {taskinstance.py:1509} INFO - Exporting the following env vars:
AIRFLOW_CTX_DAG_OWNER=***
AIRFLOW_CTX_DAG_ID=airbyte_dynamic_connection
AIRFLOW_CTX_TASK_ID=wait_for_airbyte_idle
AIRFLOW_CTX_EXECUTION_DATE=2025-08-28T11:36:24.099368+00:00
AIRFLOW_CTX_TRY_NUMBER=1
AIRFLOW_CTX_DAG_RUN_ID=manual__2025-08-28T11:36:24.099368+00:00
[2025-08-28T11:36:26.018+0000] {dynamic-airbyte-with-airflow.py:38} INFO - Job(s) still running for connection 2a2bd0be-1894-42fa-b255-7be8a5ba0726
[2025-08-28T11:36:56.896+0000] {taskinstance.py:1768} ERROR - Task failed with exception
Traceback (most recent call last):
  File "/home/airflow/.local/lib/python3.7/site-packages/urllib3/connection.py", line 175, in _new_conn
    (self._dns_host, self.port), self.timeout, **extra_kw
  File "/home/airflow/.local/lib/python3.7/site-packages/urllib3/util/connection.py", line 72, in create_connection
    for res in socket.getaddrinfo(host, port, family, socket.SOCK_STREAM):
  File "/usr/local/lib/python3.7/socket.py", line 752, in getaddrinfo
    for res in _socket.getaddrinfo(host, port, family, type, proto, flags):
socket.gaierror: [Errno -3] Temporary failure in name resolution

During handling of the above exception, another exception occurred:

Traceback (most recent call last):
  File "/home/airflow/.local/lib/python3.7/site-packages/urllib3/connectionpool.py", line 710, in urlopen
    chunked=chunked,
  File "/home/airflow/.local/lib/python3.7/site-packages/urllib3/connectionpool.py", line 398, in _make_request
    conn.request(method, url, **httplib_request_kw)
  File "/home/airflow/.local/lib/python3.7/site-packages/urllib3/connection.py", line 239, in request
    super(HTTPConnection, self).request(method, url, body=body, headers=headers)
  File "/usr/local/lib/python3.7/http/client.py", line 1281, in request
    self._send_request(method, url, body, headers, encode_chunked)
  File "/usr/local/lib/python3.7/http/client.py", line 1327, in _send_request
    self.endheaders(body, encode_chunked=encode_chunked)
  File "/usr/local/lib/python3.7/http/client.py", line 1276, in endheaders
    self._send_output(message_body, encode_chunked=encode_chunked)
  File "/usr/local/lib/python3.7/http/client.py", line 1036, in _send_output
    self.send(msg)
  File "/usr/local/lib/python3.7/http/client.py", line 976, in send
    self.connect()
  File "/home/airflow/.local/lib/python3.7/site-packages/urllib3/connection.py", line 205, in connect
    conn = self._new_conn()
  File "/home/airflow/.local/lib/python3.7/site-packages/urllib3/connection.py", line 187, in _new_conn
    self, "Failed to establish a new connection: %s" % e
urllib3.exceptions.NewConnectionError: <urllib3.connection.HTTPConnection object at 0xffff7e124e50>: Failed to establish a new connection: [Errno -3] Temporary failure in name resolution

During handling of the above exception, another exception occurred:

Traceback (most recent call last):
  File "/home/airflow/.local/lib/python3.7/site-packages/requests/adapters.py", line 499, in send
    timeout=timeout,
  File "/home/airflow/.local/lib/python3.7/site-packages/urllib3/connectionpool.py", line 788, in urlopen
    method, url, error=e, _pool=self, _stacktrace=sys.exc_info()[2]
  File "/home/airflow/.local/lib/python3.7/site-packages/urllib3/util/retry.py", line 592, in increment
    raise MaxRetryError(_pool, url, error or ResponseError(cause))
urllib3.exceptions.MaxRetryError: HTTPConnectionPool(host='host.docker.internal', port=8001): Max retries exceeded with url: /api/v1/jobs/list (Caused by NewConnectionError('<urllib3.connection.HTTPConnection object at 0xffff7e124e50>: Failed to establish a new connection: [Errno -3] Temporary failure in name resolution'))

During handling of the above exception, another exception occurred:

Traceback (most recent call last):
  File "/home/airflow/.local/lib/python3.7/site-packages/airflow/sensors/base.py", line 199, in execute
    poke_return = self.poke(context)
  File "/opt/airflow/dags/dynamic-airbyte-with-airflow.py", line 26, in poke
    "configTypes": ["sync", "reset_connection"]
  File "/home/airflow/.local/lib/python3.7/site-packages/requests/api.py", line 115, in post
    return request("post", url, data=data, json=json, **kwargs)
  File "/home/airflow/.local/lib/python3.7/site-packages/requests/api.py", line 59, in request
    return session.request(method=method, url=url, **kwargs)
  File "/home/airflow/.local/lib/python3.7/site-packages/requests/sessions.py", line 587, in request
    resp = self.send(prep, **send_kwargs)
  File "/home/airflow/.local/lib/python3.7/site-packages/requests/sessions.py", line 701, in send
    r = adapter.send(request, **kwargs)
  File "/home/airflow/.local/lib/python3.7/site-packages/requests/adapters.py", line 565, in send
    raise ConnectionError(e, request=request)
requests.exceptions.ConnectionError: HTTPConnectionPool(host='host.docker.internal', port=8001): Max retries exceeded with url: /api/v1/jobs/list (Caused by NewConnectionError('<urllib3.connection.HTTPConnection object at 0xffff7e124e50>: Failed to establish a new connection: [Errno -3] Temporary failure in name resolution'))
[2025-08-28T11:36:57.243+0000] {taskinstance.py:1323} INFO - Marking task as FAILED. dag_id=airbyte_dynamic_connection, task_id=wait_for_airbyte_idle, execution_date=20250828T113624, start_date=20250828T113625, end_date=20250828T113657
[2025-08-28T11:36:57.310+0000] {standard_task_runner.py:105} ERROR - Failed to execute job 48 for task wait_for_airbyte_idle (HTTPConnectionPool(host='host.docker.internal', port=8001): Max retries exceeded with url: /api/v1/jobs/list (Caused by NewConnectionError('<urllib3.connection.HTTPConnection object at 0xffff7e124e50>: Failed to establish a new connection: [Errno -3] Temporary failure in name resolution')); 1274)
[2025-08-28T11:36:57.335+0000] {local_task_job.py:208} INFO - Task exited with return code 1
[2025-08-28T11:36:57.453+0000] {taskinstance.py:2578} INFO - 0 downstream tasks scheduled from follow-on schedule check
