[2025-08-28T11:22:47.009+0000] {taskinstance.py:1083} INFO - Dependencies all met for <TaskInstance: airbyte_dynamic_connection.wait_for_airbyte_idle manual__2025-08-28T11:19:02.440577+00:00 [queued]>
[2025-08-28T11:22:47.014+0000] {taskinstance.py:1083} INFO - Dependencies all met for <TaskInstance: airbyte_dynamic_connection.wait_for_airbyte_idle manual__2025-08-28T11:19:02.440577+00:00 [queued]>
[2025-08-28T11:22:47.014+0000] {taskinstance.py:1279} INFO - 
--------------------------------------------------------------------------------
[2025-08-28T11:22:47.014+0000] {taskinstance.py:1280} INFO - Starting attempt 1 of 1
[2025-08-28T11:22:47.014+0000] {taskinstance.py:1281} INFO - 
--------------------------------------------------------------------------------
[2025-08-28T11:22:47.020+0000] {taskinstance.py:1300} INFO - Executing <Task(AirbyteJobSensor): wait_for_airbyte_idle> on 2025-08-28 11:19:02.440577+00:00
[2025-08-28T11:22:47.023+0000] {standard_task_runner.py:55} INFO - Started process 61 to run task
[2025-08-28T11:22:47.025+0000] {standard_task_runner.py:82} INFO - Running: ['***', 'tasks', 'run', 'airbyte_dynamic_connection', 'wait_for_airbyte_idle', 'manual__2025-08-28T11:19:02.440577+00:00', '--job-id', '42', '--raw', '--subdir', 'DAGS_FOLDER/dynamic-airbyte-with-***.py', '--cfg-path', '/tmp/tmp8pcs5cb3']
[2025-08-28T11:22:47.025+0000] {standard_task_runner.py:83} INFO - Job 42: Subtask wait_for_airbyte_idle
[2025-08-28T11:22:47.056+0000] {task_command.py:388} INFO - Running <TaskInstance: airbyte_dynamic_connection.wait_for_airbyte_idle manual__2025-08-28T11:19:02.440577+00:00 [running]> on host 966b32814b47
[2025-08-28T11:22:47.134+0000] {taskinstance.py:1509} INFO - Exporting the following env vars:
AIRFLOW_CTX_DAG_OWNER=***
AIRFLOW_CTX_DAG_ID=airbyte_dynamic_connection
AIRFLOW_CTX_TASK_ID=wait_for_airbyte_idle
AIRFLOW_CTX_EXECUTION_DATE=2025-08-28T11:19:02.440577+00:00
AIRFLOW_CTX_TRY_NUMBER=1
AIRFLOW_CTX_DAG_RUN_ID=manual__2025-08-28T11:19:02.440577+00:00
[2025-08-28T11:22:47.179+0000] {logging_mixin.py:137} WARNING - --- Logging error ---
[2025-08-28T11:22:47.180+0000] {logging_mixin.py:137} WARNING - Traceback (most recent call last):
[2025-08-28T11:22:47.181+0000] {logging_mixin.py:137} WARNING -   File "/usr/local/lib/python3.7/logging/__init__.py", line 1025, in emit
    msg = self.format(record)
[2025-08-28T11:22:47.181+0000] {logging_mixin.py:137} WARNING -   File "/usr/local/lib/python3.7/logging/__init__.py", line 869, in format
    return fmt.format(record)
[2025-08-28T11:22:47.181+0000] {logging_mixin.py:137} WARNING -   File "/usr/local/lib/python3.7/logging/__init__.py", line 608, in format
    record.message = record.getMessage()
[2025-08-28T11:22:47.181+0000] {logging_mixin.py:137} WARNING -   File "/usr/local/lib/python3.7/logging/__init__.py", line 369, in getMessage
    msg = msg % self.args
[2025-08-28T11:22:47.181+0000] {logging_mixin.py:137} WARNING - TypeError: not all arguments converted during string formatting
[2025-08-28T11:22:47.182+0000] {logging_mixin.py:137} WARNING - Call stack:
[2025-08-28T11:22:47.197+0000] {logging_mixin.py:137} WARNING -   File "/home/***/.local/bin/***", line 8, in <module>
    sys.exit(main())
[2025-08-28T11:22:47.197+0000] {logging_mixin.py:137} WARNING -   File "/home/***/.local/lib/python3.7/site-packages/***/__main__.py", line 39, in main
    args.func(args)
[2025-08-28T11:22:47.197+0000] {logging_mixin.py:137} WARNING -   File "/home/***/.local/lib/python3.7/site-packages/***/cli/cli_parser.py", line 52, in command
    return func(*args, **kwargs)
[2025-08-28T11:22:47.197+0000] {logging_mixin.py:137} WARNING -   File "/home/***/.local/lib/python3.7/site-packages/***/utils/cli.py", line 108, in wrapper
    return f(*args, **kwargs)
[2025-08-28T11:22:47.197+0000] {logging_mixin.py:137} WARNING -   File "/home/***/.local/lib/python3.7/site-packages/***/cli/commands/celery_command.py", line 200, in worker
    celery_app.worker_main(options)
[2025-08-28T11:22:47.197+0000] {logging_mixin.py:137} WARNING -   File "/home/***/.local/lib/python3.7/site-packages/celery/app/base.py", line 391, in worker_main
    self.start(argv=argv)
[2025-08-28T11:22:47.198+0000] {logging_mixin.py:137} WARNING -   File "/home/***/.local/lib/python3.7/site-packages/celery/app/base.py", line 371, in start
    celery.main(args=argv, standalone_mode=False)
[2025-08-28T11:22:47.198+0000] {logging_mixin.py:137} WARNING -   File "/home/***/.local/lib/python3.7/site-packages/click/core.py", line 1055, in main
    rv = self.invoke(ctx)
[2025-08-28T11:22:47.198+0000] {logging_mixin.py:137} WARNING -   File "/home/***/.local/lib/python3.7/site-packages/click/core.py", line 1657, in invoke
    return _process_result(sub_ctx.command.invoke(sub_ctx))
[2025-08-28T11:22:47.198+0000] {logging_mixin.py:137} WARNING -   File "/home/***/.local/lib/python3.7/site-packages/click/core.py", line 1404, in invoke
    return ctx.invoke(self.callback, **ctx.params)
[2025-08-28T11:22:47.198+0000] {logging_mixin.py:137} WARNING -   File "/home/***/.local/lib/python3.7/site-packages/click/core.py", line 760, in invoke
    return __callback(*args, **kwargs)
[2025-08-28T11:22:47.198+0000] {logging_mixin.py:137} WARNING -   File "/home/***/.local/lib/python3.7/site-packages/click/decorators.py", line 26, in new_func
    return f(get_current_context(), *args, **kwargs)
[2025-08-28T11:22:47.198+0000] {logging_mixin.py:137} WARNING -   File "/home/***/.local/lib/python3.7/site-packages/celery/bin/base.py", line 134, in caller
    return f(ctx, *args, **kwargs)
[2025-08-28T11:22:47.198+0000] {logging_mixin.py:137} WARNING -   File "/home/***/.local/lib/python3.7/site-packages/celery/bin/worker.py", line 351, in worker
    worker.start()
[2025-08-28T11:22:47.198+0000] {logging_mixin.py:137} WARNING -   File "/home/***/.local/lib/python3.7/site-packages/celery/worker/worker.py", line 203, in start
    self.blueprint.start(self)
[2025-08-28T11:22:47.198+0000] {logging_mixin.py:137} WARNING -   File "/home/***/.local/lib/python3.7/site-packages/celery/bootsteps.py", line 116, in start
    step.start(parent)
[2025-08-28T11:22:47.199+0000] {logging_mixin.py:137} WARNING -   File "/home/***/.local/lib/python3.7/site-packages/celery/bootsteps.py", line 365, in start
    return self.obj.start()
[2025-08-28T11:22:47.199+0000] {logging_mixin.py:137} WARNING -   File "/home/***/.local/lib/python3.7/site-packages/celery/concurrency/base.py", line 129, in start
    self.on_start()
[2025-08-28T11:22:47.199+0000] {logging_mixin.py:137} WARNING -   File "/home/***/.local/lib/python3.7/site-packages/celery/concurrency/prefork.py", line 115, in on_start
    **self.options)
[2025-08-28T11:22:47.199+0000] {logging_mixin.py:137} WARNING -   File "/home/***/.local/lib/python3.7/site-packages/celery/concurrency/asynpool.py", line 463, in __init__
    super().__init__(processes, *args, **kwargs)
[2025-08-28T11:22:47.199+0000] {logging_mixin.py:137} WARNING -   File "/home/***/.local/lib/python3.7/site-packages/billiard/pool.py", line 1046, in __init__
    self._create_worker_process(i)
[2025-08-28T11:22:47.199+0000] {logging_mixin.py:137} WARNING -   File "/home/***/.local/lib/python3.7/site-packages/celery/concurrency/asynpool.py", line 480, in _create_worker_process
    return super()._create_worker_process(i)
[2025-08-28T11:22:47.199+0000] {logging_mixin.py:137} WARNING -   File "/home/***/.local/lib/python3.7/site-packages/billiard/pool.py", line 1158, in _create_worker_process
    w.start()
[2025-08-28T11:22:47.199+0000] {logging_mixin.py:137} WARNING -   File "/home/***/.local/lib/python3.7/site-packages/billiard/process.py", line 124, in start
    self._popen = self._Popen(self)
[2025-08-28T11:22:47.199+0000] {logging_mixin.py:137} WARNING -   File "/home/***/.local/lib/python3.7/site-packages/billiard/context.py", line 333, in _Popen
    return Popen(process_obj)
[2025-08-28T11:22:47.200+0000] {logging_mixin.py:137} WARNING -   File "/home/***/.local/lib/python3.7/site-packages/billiard/popen_fork.py", line 24, in __init__
    self._launch(process_obj)
[2025-08-28T11:22:47.200+0000] {logging_mixin.py:137} WARNING -   File "/home/***/.local/lib/python3.7/site-packages/billiard/popen_fork.py", line 79, in _launch
    code = process_obj._bootstrap()
[2025-08-28T11:22:47.200+0000] {logging_mixin.py:137} WARNING -   File "/home/***/.local/lib/python3.7/site-packages/billiard/process.py", line 327, in _bootstrap
    self.run()
[2025-08-28T11:22:47.200+0000] {logging_mixin.py:137} WARNING -   File "/home/***/.local/lib/python3.7/site-packages/billiard/process.py", line 114, in run
    self._target(*self._args, **self._kwargs)
[2025-08-28T11:22:47.200+0000] {logging_mixin.py:137} WARNING -   File "/home/***/.local/lib/python3.7/site-packages/billiard/pool.py", line 292, in __call__
    sys.exit(self.workloop(pid=pid))
[2025-08-28T11:22:47.200+0000] {logging_mixin.py:137} WARNING -   File "/home/***/.local/lib/python3.7/site-packages/billiard/pool.py", line 362, in workloop
    result = (True, prepare_result(fun(*args, **kwargs)))
[2025-08-28T11:22:47.200+0000] {logging_mixin.py:137} WARNING -   File "/home/***/.local/lib/python3.7/site-packages/celery/app/trace.py", line 650, in fast_trace_task
    uuid, args, kwargs, request,
[2025-08-28T11:22:47.200+0000] {logging_mixin.py:137} WARNING -   File "/home/***/.local/lib/python3.7/site-packages/celery/app/trace.py", line 451, in trace_task
    R = retval = fun(*args, **kwargs)
[2025-08-28T11:22:47.200+0000] {logging_mixin.py:137} WARNING -   File "/home/***/.local/lib/python3.7/site-packages/celery/app/trace.py", line 734, in __protected_call__
    return self.run(*args, **kwargs)
[2025-08-28T11:22:47.200+0000] {logging_mixin.py:137} WARNING -   File "/home/***/.local/lib/python3.7/site-packages/***/executors/celery_executor.py", line 96, in execute_command
    _execute_in_fork(command_to_exec, celery_task_id)
[2025-08-28T11:22:47.201+0000] {logging_mixin.py:137} WARNING -   File "/home/***/.local/lib/python3.7/site-packages/***/executors/celery_executor.py", line 130, in _execute_in_fork
    args.func(args)
[2025-08-28T11:22:47.201+0000] {logging_mixin.py:137} WARNING -   File "/home/***/.local/lib/python3.7/site-packages/***/cli/cli_parser.py", line 52, in command
    return func(*args, **kwargs)
[2025-08-28T11:22:47.201+0000] {logging_mixin.py:137} WARNING -   File "/home/***/.local/lib/python3.7/site-packages/***/utils/cli.py", line 108, in wrapper
    return f(*args, **kwargs)
[2025-08-28T11:22:47.201+0000] {logging_mixin.py:137} WARNING -   File "/home/***/.local/lib/python3.7/site-packages/***/cli/commands/task_command.py", line 395, in task_run
    _run_task_by_selected_method(args, dag, ti)
[2025-08-28T11:22:47.201+0000] {logging_mixin.py:137} WARNING -   File "/home/***/.local/lib/python3.7/site-packages/***/cli/commands/task_command.py", line 193, in _run_task_by_selected_method
    _run_task_by_local_task_job(args, ti)
[2025-08-28T11:22:47.201+0000] {logging_mixin.py:137} WARNING -   File "/home/***/.local/lib/python3.7/site-packages/***/cli/commands/task_command.py", line 252, in _run_task_by_local_task_job
    run_job.run()
[2025-08-28T11:22:47.201+0000] {logging_mixin.py:137} WARNING -   File "/home/***/.local/lib/python3.7/site-packages/***/jobs/base_job.py", line 258, in run
    self._execute()
[2025-08-28T11:22:47.201+0000] {logging_mixin.py:137} WARNING -   File "/home/***/.local/lib/python3.7/site-packages/***/jobs/local_task_job.py", line 151, in _execute
    self.task_runner.start()
[2025-08-28T11:22:47.201+0000] {logging_mixin.py:137} WARNING -   File "/home/***/.local/lib/python3.7/site-packages/***/task/task_runner/standard_task_runner.py", line 43, in start
    self.process = self._start_by_fork()
[2025-08-28T11:22:47.201+0000] {logging_mixin.py:137} WARNING -   File "/home/***/.local/lib/python3.7/site-packages/***/task/task_runner/standard_task_runner.py", line 95, in _start_by_fork
    args.func(args, dag=self.dag)
[2025-08-28T11:22:47.201+0000] {logging_mixin.py:137} WARNING -   File "/home/***/.local/lib/python3.7/site-packages/***/cli/cli_parser.py", line 52, in command
    return func(*args, **kwargs)
[2025-08-28T11:22:47.202+0000] {logging_mixin.py:137} WARNING -   File "/home/***/.local/lib/python3.7/site-packages/***/utils/cli.py", line 108, in wrapper
    return f(*args, **kwargs)
[2025-08-28T11:22:47.202+0000] {logging_mixin.py:137} WARNING -   File "/home/***/.local/lib/python3.7/site-packages/***/cli/commands/task_command.py", line 395, in task_run
    _run_task_by_selected_method(args, dag, ti)
[2025-08-28T11:22:47.202+0000] {logging_mixin.py:137} WARNING -   File "/home/***/.local/lib/python3.7/site-packages/***/cli/commands/task_command.py", line 195, in _run_task_by_selected_method
    _run_raw_task(args, ti)
[2025-08-28T11:22:47.202+0000] {logging_mixin.py:137} WARNING -   File "/home/***/.local/lib/python3.7/site-packages/***/cli/commands/task_command.py", line 272, in _run_raw_task
    pool=args.pool,
[2025-08-28T11:22:47.202+0000] {logging_mixin.py:137} WARNING -   File "/home/***/.local/lib/python3.7/site-packages/***/utils/session.py", line 75, in wrapper
    return func(*args, session=session, **kwargs)
[2025-08-28T11:22:47.202+0000] {logging_mixin.py:137} WARNING -   File "/home/***/.local/lib/python3.7/site-packages/***/models/taskinstance.py", line 1374, in _run_raw_task
    self._execute_task_with_callbacks(context, test_mode)
[2025-08-28T11:22:47.202+0000] {logging_mixin.py:137} WARNING -   File "/home/***/.local/lib/python3.7/site-packages/***/models/taskinstance.py", line 1520, in _execute_task_with_callbacks
    result = self._execute_task(context, task_orig)
[2025-08-28T11:22:47.202+0000] {logging_mixin.py:137} WARNING -   File "/home/***/.local/lib/python3.7/site-packages/***/models/taskinstance.py", line 1581, in _execute_task
    result = execute_callable(context=context)
[2025-08-28T11:22:47.202+0000] {logging_mixin.py:137} WARNING -   File "/home/***/.local/lib/python3.7/site-packages/***/sensors/base.py", line 199, in execute
    poke_return = self.poke(context)
[2025-08-28T11:22:47.203+0000] {logging_mixin.py:137} WARNING -   File "/opt/***/dags/dynamic-airbyte-with-***.py", line 29, in poke
    self.log.info("Airbyte API error:", resp.status_code, resp.text)
[2025-08-28T11:22:47.203+0000] {logging_mixin.py:137} WARNING -   File "/usr/local/lib/python3.7/logging/__init__.py", line 1378, in info
    self._log(INFO, msg, args, **kwargs)
[2025-08-28T11:22:47.203+0000] {logging_mixin.py:137} WARNING -   File "/usr/local/lib/python3.7/logging/__init__.py", line 1514, in _log
    self.handle(record)
[2025-08-28T11:22:47.203+0000] {logging_mixin.py:137} WARNING -   File "/usr/local/lib/python3.7/logging/__init__.py", line 1524, in handle
    self.callHandlers(record)
[2025-08-28T11:22:47.203+0000] {logging_mixin.py:137} WARNING -   File "/usr/local/lib/python3.7/logging/__init__.py", line 1586, in callHandlers
    hdlr.handle(record)
[2025-08-28T11:22:47.203+0000] {logging_mixin.py:137} WARNING -   File "/usr/local/lib/python3.7/logging/__init__.py", line 894, in handle
    self.emit(record)
[2025-08-28T11:22:47.203+0000] {logging_mixin.py:137} WARNING -   File "/home/***/.local/lib/python3.7/site-packages/***/utils/log/file_task_handler.py", line 80, in emit
    self.handler.emit(record)
[2025-08-28T11:22:47.203+0000] {logging_mixin.py:137} WARNING - Message: 'Airbyte API error:'
Arguments: (500, '{"message":"Internal Server Error: Must include at least one configType.","exceptionClassName":"java.lang.IllegalStateException","exceptionStack":[],"rootCauseExceptionStack":[]}')
[2025-08-28T11:22:47.203+0000] {taskinstance.py:1768} ERROR - Task failed with exception
Traceback (most recent call last):
  File "/home/airflow/.local/lib/python3.7/site-packages/airflow/sensors/base.py", line 199, in execute
    poke_return = self.poke(context)
  File "/opt/airflow/dags/dynamic-airbyte-with-airflow.py", line 30, in poke
    resp.raise_for_status()
  File "/home/airflow/.local/lib/python3.7/site-packages/requests/models.py", line 1021, in raise_for_status
    raise HTTPError(http_error_msg, response=self)
requests.exceptions.HTTPError: 500 Server Error: Internal Server Error for url: http://host.docker.internal:8001/api/v1/jobs/list
[2025-08-28T11:22:47.209+0000] {taskinstance.py:1323} INFO - Marking task as FAILED. dag_id=airbyte_dynamic_connection, task_id=wait_for_airbyte_idle, execution_date=20250828T111902, start_date=20250828T112247, end_date=20250828T112247
[2025-08-28T11:22:47.218+0000] {standard_task_runner.py:105} ERROR - Failed to execute job 42 for task wait_for_airbyte_idle (500 Server Error: Internal Server Error for url: http://host.docker.internal:8001/api/v1/jobs/list; 61)
[2025-08-28T11:22:47.247+0000] {local_task_job.py:208} INFO - Task exited with return code 1
[2025-08-28T11:22:47.263+0000] {taskinstance.py:2578} INFO - 0 downstream tasks scheduled from follow-on schedule check
