[2025-08-31T14:13:19.753+0000] {taskinstance.py:1083} INFO - Dependencies all met for <TaskInstance: airbyte_dynamic_connection.create_airbyte_connection manual__2025-08-31T14:12:11+00:00 [queued]>
[2025-08-31T14:13:19.760+0000] {taskinstance.py:1083} INFO - Dependencies all met for <TaskInstance: airbyte_dynamic_connection.create_airbyte_connection manual__2025-08-31T14:12:11+00:00 [queued]>
[2025-08-31T14:13:19.761+0000] {taskinstance.py:1279} INFO - 
--------------------------------------------------------------------------------
[2025-08-31T14:13:19.761+0000] {taskinstance.py:1280} INFO - Starting attempt 1 of 1
[2025-08-31T14:13:19.761+0000] {taskinstance.py:1281} INFO - 
--------------------------------------------------------------------------------
[2025-08-31T14:13:19.767+0000] {taskinstance.py:1300} INFO - Executing <Task(AirbyteConnectionCreator): create_airbyte_connection> on 2025-08-31 14:12:11+00:00
[2025-08-31T14:13:19.769+0000] {standard_task_runner.py:55} INFO - Started process 388 to run task
[2025-08-31T14:13:19.771+0000] {standard_task_runner.py:82} INFO - Running: ['***', 'tasks', 'run', 'airbyte_dynamic_connection', 'create_airbyte_connection', 'manual__2025-08-31T14:12:11+00:00', '--job-id', '177', '--raw', '--subdir', 'DAGS_FOLDER/dynamic-airbyte-with-***.py', '--cfg-path', '/tmp/tmpapc37yy_']
[2025-08-31T14:13:19.771+0000] {standard_task_runner.py:83} INFO - Job 177: Subtask create_airbyte_connection
[2025-08-31T14:13:19.801+0000] {task_command.py:388} INFO - Running <TaskInstance: airbyte_dynamic_connection.create_airbyte_connection manual__2025-08-31T14:12:11+00:00 [running]> on host 966b32814b47
[2025-08-31T14:13:19.831+0000] {taskinstance.py:1509} INFO - Exporting the following env vars:
AIRFLOW_CTX_DAG_OWNER=***
AIRFLOW_CTX_DAG_ID=airbyte_dynamic_connection
AIRFLOW_CTX_TASK_ID=create_airbyte_connection
AIRFLOW_CTX_EXECUTION_DATE=2025-08-31T14:12:11+00:00
AIRFLOW_CTX_TRY_NUMBER=1
AIRFLOW_CTX_DAG_RUN_ID=manual__2025-08-31T14:12:11+00:00
[2025-08-31T14:13:19.989+0000] {dynamic-airbyte-with-airflow.py:114} INFO - âœ… Created Airbyte connection: 106afd7b-83c4-4e72-bcf6-8cc548732b7d
[2025-08-31T14:13:39.993+0000] {dynamic-airbyte-with-airflow.py:121} INFO - Airbyte connection already created: 106afd7b-83c4-4e72-bcf6-8cc548732b7d
[2025-08-31T14:13:40.015+0000] {taskinstance.py:1768} ERROR - Task failed with exception
Traceback (most recent call last):
  File "/home/airflow/.local/lib/python3.7/site-packages/urllib3/connectionpool.py", line 710, in urlopen
    chunked=chunked,
  File "/home/airflow/.local/lib/python3.7/site-packages/urllib3/connectionpool.py", line 449, in _make_request
    six.raise_from(e, None)
  File "<string>", line 3, in raise_from
  File "/home/airflow/.local/lib/python3.7/site-packages/urllib3/connectionpool.py", line 444, in _make_request
    httplib_response = conn.getresponse()
  File "/usr/local/lib/python3.7/http/client.py", line 1373, in getresponse
    response.begin()
  File "/usr/local/lib/python3.7/http/client.py", line 319, in begin
    version, status, reason = self._read_status()
  File "/usr/local/lib/python3.7/http/client.py", line 288, in _read_status
    raise RemoteDisconnected("Remote end closed connection without"
http.client.RemoteDisconnected: Remote end closed connection without response

During handling of the above exception, another exception occurred:

Traceback (most recent call last):
  File "/home/airflow/.local/lib/python3.7/site-packages/requests/adapters.py", line 499, in send
    timeout=timeout,
  File "/home/airflow/.local/lib/python3.7/site-packages/urllib3/connectionpool.py", line 788, in urlopen
    method, url, error=e, _pool=self, _stacktrace=sys.exc_info()[2]
  File "/home/airflow/.local/lib/python3.7/site-packages/urllib3/util/retry.py", line 550, in increment
    raise six.reraise(type(error), error, _stacktrace)
  File "/home/airflow/.local/lib/python3.7/site-packages/urllib3/packages/six.py", line 769, in reraise
    raise value.with_traceback(tb)
  File "/home/airflow/.local/lib/python3.7/site-packages/urllib3/connectionpool.py", line 710, in urlopen
    chunked=chunked,
  File "/home/airflow/.local/lib/python3.7/site-packages/urllib3/connectionpool.py", line 449, in _make_request
    six.raise_from(e, None)
  File "<string>", line 3, in raise_from
  File "/home/airflow/.local/lib/python3.7/site-packages/urllib3/connectionpool.py", line 444, in _make_request
    httplib_response = conn.getresponse()
  File "/usr/local/lib/python3.7/http/client.py", line 1373, in getresponse
    response.begin()
  File "/usr/local/lib/python3.7/http/client.py", line 319, in begin
    version, status, reason = self._read_status()
  File "/usr/local/lib/python3.7/http/client.py", line 288, in _read_status
    raise RemoteDisconnected("Remote end closed connection without"
urllib3.exceptions.ProtocolError: ('Connection aborted.', RemoteDisconnected('Remote end closed connection without response'))

During handling of the above exception, another exception occurred:

Traceback (most recent call last):
  File "/home/airflow/.local/lib/python3.7/site-packages/airflow/sensors/base.py", line 199, in execute
    poke_return = self.poke(context)
  File "/opt/airflow/dags/dynamic-airbyte-with-airflow.py", line 126, in poke
    "configTypes": ["sync", "reset_connection"]
  File "/home/airflow/.local/lib/python3.7/site-packages/requests/api.py", line 115, in post
    return request("post", url, data=data, json=json, **kwargs)
  File "/home/airflow/.local/lib/python3.7/site-packages/requests/api.py", line 59, in request
    return session.request(method=method, url=url, **kwargs)
  File "/home/airflow/.local/lib/python3.7/site-packages/requests/sessions.py", line 587, in request
    resp = self.send(prep, **send_kwargs)
  File "/home/airflow/.local/lib/python3.7/site-packages/requests/sessions.py", line 701, in send
    r = adapter.send(request, **kwargs)
  File "/home/airflow/.local/lib/python3.7/site-packages/requests/adapters.py", line 547, in send
    raise ConnectionError(err, request=request)
requests.exceptions.ConnectionError: ('Connection aborted.', RemoteDisconnected('Remote end closed connection without response'))
[2025-08-31T14:13:40.027+0000] {taskinstance.py:1323} INFO - Marking task as FAILED. dag_id=airbyte_dynamic_connection, task_id=create_airbyte_connection, execution_date=20250831T141211, start_date=20250831T141319, end_date=20250831T141340
[2025-08-31T14:13:40.035+0000] {standard_task_runner.py:105} ERROR - Failed to execute job 177 for task create_airbyte_connection (('Connection aborted.', RemoteDisconnected('Remote end closed connection without response')); 388)
[2025-08-31T14:13:40.048+0000] {local_task_job.py:208} INFO - Task exited with return code 1
[2025-08-31T14:13:40.061+0000] {taskinstance.py:2578} INFO - 0 downstream tasks scheduled from follow-on schedule check
