[2025-08-28T12:51:06.457+0000] {taskinstance.py:1083} INFO - Dependencies all met for <TaskInstance: airbyte_dynamic_connection.discover_schema manual__2025-08-28T12:51:05.454954+00:00 [queued]>
[2025-08-28T12:51:06.462+0000] {taskinstance.py:1083} INFO - Dependencies all met for <TaskInstance: airbyte_dynamic_connection.discover_schema manual__2025-08-28T12:51:05.454954+00:00 [queued]>
[2025-08-28T12:51:06.462+0000] {taskinstance.py:1279} INFO - 
--------------------------------------------------------------------------------
[2025-08-28T12:51:06.462+0000] {taskinstance.py:1280} INFO - Starting attempt 1 of 1
[2025-08-28T12:51:06.462+0000] {taskinstance.py:1281} INFO - 
--------------------------------------------------------------------------------
[2025-08-28T12:51:06.469+0000] {taskinstance.py:1300} INFO - Executing <Task(PythonOperator): discover_schema> on 2025-08-28 12:51:05.454954+00:00
[2025-08-28T12:51:06.472+0000] {standard_task_runner.py:55} INFO - Started process 4133 to run task
[2025-08-28T12:51:06.475+0000] {standard_task_runner.py:82} INFO - Running: ['***', 'tasks', 'run', 'airbyte_dynamic_connection', 'discover_schema', 'manual__2025-08-28T12:51:05.454954+00:00', '--job-id', '116', '--raw', '--subdir', 'DAGS_FOLDER/dynamic-airbyte-with-***.py', '--cfg-path', '/tmp/tmposaefhcf']
[2025-08-28T12:51:06.475+0000] {standard_task_runner.py:83} INFO - Job 116: Subtask discover_schema
[2025-08-28T12:51:06.510+0000] {task_command.py:388} INFO - Running <TaskInstance: airbyte_dynamic_connection.discover_schema manual__2025-08-28T12:51:05.454954+00:00 [running]> on host 966b32814b47
[2025-08-28T12:51:06.548+0000] {taskinstance.py:1509} INFO - Exporting the following env vars:
AIRFLOW_CTX_DAG_OWNER=***
AIRFLOW_CTX_DAG_ID=airbyte_dynamic_connection
AIRFLOW_CTX_TASK_ID=discover_schema
AIRFLOW_CTX_EXECUTION_DATE=2025-08-28T12:51:05.454954+00:00
AIRFLOW_CTX_TRY_NUMBER=1
AIRFLOW_CTX_DAG_RUN_ID=manual__2025-08-28T12:51:05.454954+00:00
[2025-08-28T12:51:06.557+0000] {taskinstance.py:1768} ERROR - Task failed with exception
Traceback (most recent call last):
  File "/home/airflow/.local/lib/python3.7/site-packages/urllib3/connection.py", line 175, in _new_conn
    (self._dns_host, self.port), self.timeout, **extra_kw
  File "/home/airflow/.local/lib/python3.7/site-packages/urllib3/util/connection.py", line 95, in create_connection
    raise err
  File "/home/airflow/.local/lib/python3.7/site-packages/urllib3/util/connection.py", line 85, in create_connection
    sock.connect(sa)
ConnectionRefusedError: [Errno 111] Connection refused

During handling of the above exception, another exception occurred:

Traceback (most recent call last):
  File "/home/airflow/.local/lib/python3.7/site-packages/urllib3/connectionpool.py", line 710, in urlopen
    chunked=chunked,
  File "/home/airflow/.local/lib/python3.7/site-packages/urllib3/connectionpool.py", line 398, in _make_request
    conn.request(method, url, **httplib_request_kw)
  File "/home/airflow/.local/lib/python3.7/site-packages/urllib3/connection.py", line 239, in request
    super(HTTPConnection, self).request(method, url, body=body, headers=headers)
  File "/usr/local/lib/python3.7/http/client.py", line 1281, in request
    self._send_request(method, url, body, headers, encode_chunked)
  File "/usr/local/lib/python3.7/http/client.py", line 1327, in _send_request
    self.endheaders(body, encode_chunked=encode_chunked)
  File "/usr/local/lib/python3.7/http/client.py", line 1276, in endheaders
    self._send_output(message_body, encode_chunked=encode_chunked)
  File "/usr/local/lib/python3.7/http/client.py", line 1036, in _send_output
    self.send(msg)
  File "/usr/local/lib/python3.7/http/client.py", line 976, in send
    self.connect()
  File "/home/airflow/.local/lib/python3.7/site-packages/urllib3/connection.py", line 205, in connect
    conn = self._new_conn()
  File "/home/airflow/.local/lib/python3.7/site-packages/urllib3/connection.py", line 187, in _new_conn
    self, "Failed to establish a new connection: %s" % e
urllib3.exceptions.NewConnectionError: <urllib3.connection.HTTPConnection object at 0xffffacb84dd0>: Failed to establish a new connection: [Errno 111] Connection refused

During handling of the above exception, another exception occurred:

Traceback (most recent call last):
  File "/home/airflow/.local/lib/python3.7/site-packages/requests/adapters.py", line 499, in send
    timeout=timeout,
  File "/home/airflow/.local/lib/python3.7/site-packages/urllib3/connectionpool.py", line 788, in urlopen
    method, url, error=e, _pool=self, _stacktrace=sys.exc_info()[2]
  File "/home/airflow/.local/lib/python3.7/site-packages/urllib3/util/retry.py", line 592, in increment
    raise MaxRetryError(_pool, url, error or ResponseError(cause))
urllib3.exceptions.MaxRetryError: HTTPConnectionPool(host='host.docker.internal', port=8001): Max retries exceeded with url: /api/v1/sources/discover_schema (Caused by NewConnectionError('<urllib3.connection.HTTPConnection object at 0xffffacb84dd0>: Failed to establish a new connection: [Errno 111] Connection refused'))

During handling of the above exception, another exception occurred:

Traceback (most recent call last):
  File "/home/airflow/.local/lib/python3.7/site-packages/airflow/operators/python.py", line 175, in execute
    return_value = self.execute_callable()
  File "/home/airflow/.local/lib/python3.7/site-packages/airflow/operators/python.py", line 192, in execute_callable
    return self.python_callable(*self.op_args, **self.op_kwargs)
  File "/opt/airflow/dags/dynamic-airbyte-with-airflow.py", line 47, in discover_schema
    json={"sourceId": "304821b7-0567-41f6-af55-72fb42aa015d"},
  File "/home/airflow/.local/lib/python3.7/site-packages/requests/api.py", line 115, in post
    return request("post", url, data=data, json=json, **kwargs)
  File "/home/airflow/.local/lib/python3.7/site-packages/requests/api.py", line 59, in request
    return session.request(method=method, url=url, **kwargs)
  File "/home/airflow/.local/lib/python3.7/site-packages/requests/sessions.py", line 587, in request
    resp = self.send(prep, **send_kwargs)
  File "/home/airflow/.local/lib/python3.7/site-packages/requests/sessions.py", line 701, in send
    r = adapter.send(request, **kwargs)
  File "/home/airflow/.local/lib/python3.7/site-packages/requests/adapters.py", line 565, in send
    raise ConnectionError(e, request=request)
requests.exceptions.ConnectionError: HTTPConnectionPool(host='host.docker.internal', port=8001): Max retries exceeded with url: /api/v1/sources/discover_schema (Caused by NewConnectionError('<urllib3.connection.HTTPConnection object at 0xffffacb84dd0>: Failed to establish a new connection: [Errno 111] Connection refused'))
[2025-08-28T12:51:06.564+0000] {taskinstance.py:1323} INFO - Marking task as FAILED. dag_id=airbyte_dynamic_connection, task_id=discover_schema, execution_date=20250828T125105, start_date=20250828T125106, end_date=20250828T125106
[2025-08-28T12:51:06.570+0000] {standard_task_runner.py:105} ERROR - Failed to execute job 116 for task discover_schema (HTTPConnectionPool(host='host.docker.internal', port=8001): Max retries exceeded with url: /api/v1/sources/discover_schema (Caused by NewConnectionError('<urllib3.connection.HTTPConnection object at 0xffffacb84dd0>: Failed to establish a new connection: [Errno 111] Connection refused')); 4133)
[2025-08-28T12:51:06.614+0000] {local_task_job.py:208} INFO - Task exited with return code 1
[2025-08-28T12:51:06.625+0000] {taskinstance.py:2578} INFO - 0 downstream tasks scheduled from follow-on schedule check
