[2025-08-28T12:13:39.195+0000] {taskinstance.py:1083} INFO - Dependencies all met for <TaskInstance: airbyte_dynamic_connection.trigger_airbyte_sync manual__2025-08-28T12:12:56.306660+00:00 [queued]>
[2025-08-28T12:13:39.202+0000] {taskinstance.py:1083} INFO - Dependencies all met for <TaskInstance: airbyte_dynamic_connection.trigger_airbyte_sync manual__2025-08-28T12:12:56.306660+00:00 [queued]>
[2025-08-28T12:13:39.202+0000] {taskinstance.py:1279} INFO - 
--------------------------------------------------------------------------------
[2025-08-28T12:13:39.202+0000] {taskinstance.py:1280} INFO - Starting attempt 1 of 1
[2025-08-28T12:13:39.202+0000] {taskinstance.py:1281} INFO - 
--------------------------------------------------------------------------------
[2025-08-28T12:13:39.208+0000] {taskinstance.py:1300} INFO - Executing <Task(AirbyteTriggerSyncOperator): trigger_airbyte_sync> on 2025-08-28 12:12:56.306660+00:00
[2025-08-28T12:13:39.212+0000] {standard_task_runner.py:55} INFO - Started process 614 to run task
[2025-08-28T12:13:39.216+0000] {standard_task_runner.py:82} INFO - Running: ['***', 'tasks', 'run', 'airbyte_dynamic_connection', 'trigger_airbyte_sync', 'manual__2025-08-28T12:12:56.306660+00:00', '--job-id', '97', '--raw', '--subdir', 'DAGS_FOLDER/dynamic-airbyte-with-***.py', '--cfg-path', '/tmp/tmphoqbe5_t']
[2025-08-28T12:13:39.217+0000] {standard_task_runner.py:83} INFO - Job 97: Subtask trigger_airbyte_sync
[2025-08-28T12:13:39.255+0000] {task_command.py:388} INFO - Running <TaskInstance: airbyte_dynamic_connection.trigger_airbyte_sync manual__2025-08-28T12:12:56.306660+00:00 [running]> on host 966b32814b47
[2025-08-28T12:13:39.286+0000] {taskinstance.py:1509} INFO - Exporting the following env vars:
AIRFLOW_CTX_DAG_OWNER=***
AIRFLOW_CTX_DAG_ID=airbyte_dynamic_connection
AIRFLOW_CTX_TASK_ID=trigger_airbyte_sync
AIRFLOW_CTX_EXECUTION_DATE=2025-08-28T12:12:56.306660+00:00
AIRFLOW_CTX_TRY_NUMBER=1
AIRFLOW_CTX_DAG_RUN_ID=manual__2025-08-28T12:12:56.306660+00:00
[2025-08-28T12:13:39.290+0000] {base.py:73} INFO - Using connection ID 'test-dynamic-airbyte-with-***' for task execution.
[2025-08-28T12:13:39.519+0000] {airbyte.py:77} INFO - Job 29 was submitted to Airbyte Server
[2025-08-28T12:13:39.519+0000] {airbyte.py:79} INFO - Waiting for job 29 to complete
[2025-08-28T12:14:09.539+0000] {base.py:73} INFO - Using connection ID 'test-dynamic-airbyte-with-***' for task execution.
[2025-08-28T12:14:39.655+0000] {base.py:73} INFO - Using connection ID 'test-dynamic-airbyte-with-***' for task execution.
[2025-08-28T12:14:39.693+0000] {taskinstance.py:1768} ERROR - Task failed with exception
Traceback (most recent call last):
  File "/home/airflow/.local/lib/python3.7/site-packages/airflow/providers/airbyte/operators/airbyte.py", line 80, in execute
    self.hook.wait_for_job(job_id=self.job_id, wait_seconds=self.wait_seconds, timeout=self.timeout)
  File "/home/airflow/.local/lib/python3.7/site-packages/airflow/providers/airbyte/hooks/airbyte.py", line 84, in wait_for_job
    raise Exception(f"Encountered unexpected state `{state}` for job_id `{job_id}`")
Exception: Encountered unexpected state `failed` for job_id `29`
[2025-08-28T12:14:39.704+0000] {taskinstance.py:1323} INFO - Marking task as FAILED. dag_id=airbyte_dynamic_connection, task_id=trigger_airbyte_sync, execution_date=20250828T121256, start_date=20250828T121339, end_date=20250828T121439
[2025-08-28T12:14:39.727+0000] {standard_task_runner.py:105} ERROR - Failed to execute job 97 for task trigger_airbyte_sync (Encountered unexpected state `failed` for job_id `29`; 614)
[2025-08-28T12:14:39.767+0000] {local_task_job.py:208} INFO - Task exited with return code 1
[2025-08-28T12:14:39.781+0000] {taskinstance.py:2578} INFO - 0 downstream tasks scheduled from follow-on schedule check
