{"timestamp":"2025-09-05T06:09:15.677245","level":"info","event":"DAG bundles loaded: dags-folder, example_dags","logger":"airflow.dag_processing.bundles.manager.DagBundlesManager"}
{"timestamp":"2025-09-05T06:09:15.677914","level":"info","event":"Filling up the DagBag from /opt/airflow/dags/airbyte-and-dbt-with-airflow.py","logger":"airflow.models.dagbag.DagBag"}
{"timestamp":"2025-09-05T06:09:15.696757","level":"info","event":"Trying to parse the dbt project using dbt ls cache cosmos_cache__airbyte_dynamic_connection__my_project_dbt_group_11...","logger":"cosmos.dbt.graph"}
{"timestamp":"2025-09-05T06:09:15.737269","level":"info","event":"Cosmos performance: time to calculate cache identifier cosmos_cache__airbyte_dynamic_connection__my_project_dbt_group_11 for current version: 0.031070833007106557","logger":"cosmos.cache"}
{"timestamp":"2025-09-05T06:09:15.737422","level":"info","event":"Cosmos performance [5f5c1e41ce68|1551]: The cache size for cosmos_cache__airbyte_dynamic_connection__my_project_dbt_group_11 is 4337","logger":"cosmos.dbt.graph"}
{"timestamp":"2025-09-05T06:09:15.737689","level":"info","event":"Cosmos performance: Cache hit for cosmos_cache__airbyte_dynamic_connection__my_project_dbt_group_11 - 2499a7507d070b7bbbbe009f3f50a3a8,d41d8cd98f00b204e9800998ecf8427e","logger":"cosmos.dbt.graph"}
{"timestamp":"2025-09-05T06:09:15.738119","level":"info","event":"Total nodes: 6","logger":"cosmos.dbt.graph"}
{"timestamp":"2025-09-05T06:09:15.738157","level":"info","event":"Total filtered nodes: 6","logger":"cosmos.dbt.graph"}
{"timestamp":"2025-09-05T06:09:15.738215","level":"info","event":"Cosmos performance (airbyte_dynamic_connection__my_project_dbt_group_11) -  [5f5c1e41ce68|1551]: It took 0.0417s to parse the dbt project for DAG using LoadMode.DBT_LS_CACHE","logger":"cosmos.converter"}
{"timestamp":"2025-09-05T06:09:15.738650","level":"info","event":"Project /opt/airflow/dbt/my_project_dbt does not have {'packages.yml', 'dependencies.yml'}","logger":"cosmos.dbt.project"}
{"timestamp":"2025-09-05T06:09:15.739672","level":"info","event":"Project /opt/airflow/dbt/my_project_dbt does not have {'packages.yml', 'dependencies.yml'}","logger":"cosmos.dbt.project"}
{"timestamp":"2025-09-05T06:09:15.740651","level":"info","event":"Project /opt/airflow/dbt/my_project_dbt does not have {'packages.yml', 'dependencies.yml'}","logger":"cosmos.dbt.project"}
{"timestamp":"2025-09-05T06:09:15.741186","level":"info","event":"Project /opt/airflow/dbt/my_project_dbt does not have {'packages.yml', 'dependencies.yml'}","logger":"cosmos.dbt.project"}
{"timestamp":"2025-09-05T06:09:15.741727","level":"info","event":"Project /opt/airflow/dbt/my_project_dbt does not have {'packages.yml', 'dependencies.yml'}","logger":"cosmos.dbt.project"}
{"timestamp":"2025-09-05T06:09:15.742109","level":"info","event":"Project /opt/airflow/dbt/my_project_dbt does not have {'packages.yml', 'dependencies.yml'}","logger":"cosmos.dbt.project"}
{"timestamp":"2025-09-05T06:09:15.742960","level":"info","event":"Cosmos performance (airbyte_dynamic_connection__my_project_dbt_group_11) - [5f5c1e41ce68|1551]: It took 0.00474s to build the Airflow DAG.","logger":"cosmos.converter"}
{"timestamp":"2025-09-05T06:09:15.743714","level":"warning","event":"/home/airflow/.local/lib/python3.12/site-packages/pydantic/main.py:463: UserWarning: Pydantic serializer warnings:\n  PydanticSerializationUnexpectedValue(Expected `str` - serialized value may not be as expected [input_value={'version': '2499a7507d07...y_project_dbt_group_11'}, input_type=dict])\n  return self.__pydantic_serializer__.to_python(\n","logger":"py.warnings"}
{"timestamp":"2025-09-05T06:09:15.764962Z","level":"info","event":"Task instance is in running state","chan":"stdout","logger":"task"}
{"timestamp":"2025-09-05T06:09:15.765117Z","level":"info","event":" Previous state of the Task instance: TaskInstanceState.QUEUED","chan":"stdout","logger":"task"}
{"timestamp":"2025-09-05T06:09:15.766248Z","level":"info","event":"Current task name:ingest_weather_data","chan":"stdout","logger":"task"}
{"timestamp":"2025-09-05T06:09:15.766417Z","level":"info","event":"Dag name:airbyte_dynamic_connection","chan":"stdout","logger":"task"}
{"timestamp":"2025-09-05T06:09:19.774594","level":"error","event":"Task failed with exception","logger":"task","error_detail":[{"exc_type":"ConnectionError","exc_value":"HTTPSConnectionPool(host='api.open-meteo.com', port=443): Max retries exceeded with url: /v1/forecast?latitude=40.71&longitude=-74.01&current_weather=true (Caused by NameResolutionError(\"<urllib3.connection.HTTPSConnection object at 0xffff709fe7b0>: Failed to resolve 'api.open-meteo.com' ([Errno -5] No address associated with hostname)\"))","exc_notes":[],"syntax_error":null,"is_cause":false,"frames":[{"filename":"/home/airflow/.local/lib/python3.12/site-packages/airflow/sdk/execution_time/task_runner.py","lineno":918,"name":"run"},{"filename":"/home/airflow/.local/lib/python3.12/site-packages/airflow/sdk/execution_time/task_runner.py","lineno":1213,"name":"_execute_task"},{"filename":"/home/airflow/.local/lib/python3.12/site-packages/airflow/sdk/bases/operator.py","lineno":397,"name":"wrapper"},{"filename":"/home/airflow/.local/lib/python3.12/site-packages/airflow/providers/standard/operators/python.py","lineno":217,"name":"execute"},{"filename":"/home/airflow/.local/lib/python3.12/site-packages/airflow/providers/standard/operators/python.py","lineno":240,"name":"execute_callable"},{"filename":"/home/airflow/.local/lib/python3.12/site-packages/airflow/sdk/execution_time/callback_runner.py","lineno":81,"name":"run"},{"filename":"/opt/airflow/dags/airbyte-and-dbt-with-airflow.py","lineno":174,"name":"ingest_weather_data"},{"filename":"/home/airflow/.local/lib/python3.12/site-packages/requests/api.py","lineno":73,"name":"get"},{"filename":"/home/airflow/.local/lib/python3.12/site-packages/requests/api.py","lineno":59,"name":"request"},{"filename":"/home/airflow/.local/lib/python3.12/site-packages/requests/sessions.py","lineno":589,"name":"request"},{"filename":"/home/airflow/.local/lib/python3.12/site-packages/requests/sessions.py","lineno":703,"name":"send"},{"filename":"/home/airflow/.local/lib/python3.12/site-packages/requests/adapters.py","lineno":700,"name":"send"}],"is_group":false,"exceptions":[]},{"exc_type":"MaxRetryError","exc_value":"HTTPSConnectionPool(host='api.open-meteo.com', port=443): Max retries exceeded with url: /v1/forecast?latitude=40.71&longitude=-74.01&current_weather=true (Caused by NameResolutionError(\"<urllib3.connection.HTTPSConnection object at 0xffff709fe7b0>: Failed to resolve 'api.open-meteo.com' ([Errno -5] No address associated with hostname)\"))","exc_notes":[],"syntax_error":null,"is_cause":false,"frames":[{"filename":"/home/airflow/.local/lib/python3.12/site-packages/requests/adapters.py","lineno":667,"name":"send"},{"filename":"/home/airflow/.local/lib/python3.12/site-packages/urllib3/connectionpool.py","lineno":841,"name":"urlopen"},{"filename":"/home/airflow/.local/lib/python3.12/site-packages/urllib3/util/retry.py","lineno":519,"name":"increment"}],"is_group":false,"exceptions":[]},{"exc_type":"NameResolutionError","exc_value":"<urllib3.connection.HTTPSConnection object at 0xffff709fe7b0>: Failed to resolve 'api.open-meteo.com' ([Errno -5] No address associated with hostname)","exc_notes":[],"syntax_error":null,"is_cause":true,"frames":[{"filename":"/home/airflow/.local/lib/python3.12/site-packages/urllib3/connectionpool.py","lineno":787,"name":"urlopen"},{"filename":"/home/airflow/.local/lib/python3.12/site-packages/urllib3/connectionpool.py","lineno":488,"name":"_make_request"},{"filename":"/home/airflow/.local/lib/python3.12/site-packages/urllib3/connectionpool.py","lineno":464,"name":"_make_request"},{"filename":"/home/airflow/.local/lib/python3.12/site-packages/urllib3/connectionpool.py","lineno":1093,"name":"_validate_conn"},{"filename":"/home/airflow/.local/lib/python3.12/site-packages/urllib3/connection.py","lineno":753,"name":"connect"},{"filename":"/home/airflow/.local/lib/python3.12/site-packages/urllib3/connection.py","lineno":205,"name":"_new_conn"}],"is_group":false,"exceptions":[]},{"exc_type":"gaierror","exc_value":"[Errno -5] No address associated with hostname","exc_notes":[],"syntax_error":null,"is_cause":true,"frames":[{"filename":"/home/airflow/.local/lib/python3.12/site-packages/urllib3/connection.py","lineno":198,"name":"_new_conn"},{"filename":"/home/airflow/.local/lib/python3.12/site-packages/urllib3/util/connection.py","lineno":60,"name":"create_connection"},{"filename":"/usr/local/lib/python3.12/socket.py","lineno":978,"name":"getaddrinfo"}],"is_group":false,"exceptions":[]}]}
{"timestamp":"2025-09-05T06:09:19.778779Z","level":"info","event":"Task instance in failure state","chan":"stdout","logger":"task"}
{"timestamp":"2025-09-05T06:09:19.782146Z","level":"info","event":"Task start","chan":"stdout","logger":"task"}
{"timestamp":"2025-09-05T06:09:19.782454Z","level":"info","event":"Task:<Task(PythonOperator): ingest_weather_data>","chan":"stdout","logger":"task"}
{"timestamp":"2025-09-05T06:09:19.782635Z","level":"info","event":"Failure caused by HTTPSConnectionPool(host='api.open-meteo.com', port=443): Max retries exceeded with url: /v1/forecast?latitude=40.71&longitude=-74.01&current_weather=true (Caused by NameResolutionError(\"<urllib3.connection.HTTPSConnection object at 0xffff709fe7b0>: Failed to resolve 'api.open-meteo.com' ([Errno -5] No address associated with hostname)\"))","chan":"stdout","logger":"task"}
