[2025-08-29T14:11:50.223+0000] {taskinstance.py:1083} INFO - Dependencies all met for <TaskInstance: airbyte_dynamic_connection.wait_for_airbyte_idle manual__2025-08-29T14:11:09+00:00 [queued]>
[2025-08-29T14:11:50.228+0000] {taskinstance.py:1083} INFO - Dependencies all met for <TaskInstance: airbyte_dynamic_connection.wait_for_airbyte_idle manual__2025-08-29T14:11:09+00:00 [queued]>
[2025-08-29T14:11:50.228+0000] {taskinstance.py:1279} INFO - 
--------------------------------------------------------------------------------
[2025-08-29T14:11:50.228+0000] {taskinstance.py:1280} INFO - Starting attempt 1 of 1
[2025-08-29T14:11:50.228+0000] {taskinstance.py:1281} INFO - 
--------------------------------------------------------------------------------
[2025-08-29T14:11:50.234+0000] {taskinstance.py:1300} INFO - Executing <Task(AirbyteJobSensor): wait_for_airbyte_idle> on 2025-08-29 14:11:09+00:00
[2025-08-29T14:11:50.236+0000] {standard_task_runner.py:55} INFO - Started process 18219 to run task
[2025-08-29T14:11:50.237+0000] {standard_task_runner.py:82} INFO - Running: ['***', 'tasks', 'run', 'airbyte_dynamic_connection', 'wait_for_airbyte_idle', 'manual__2025-08-29T14:11:09+00:00', '--job-id', '136', '--raw', '--subdir', 'DAGS_FOLDER/dynamic-airbyte-with-***.py', '--cfg-path', '/tmp/tmp7_sbqs0b']
[2025-08-29T14:11:50.238+0000] {standard_task_runner.py:83} INFO - Job 136: Subtask wait_for_airbyte_idle
[2025-08-29T14:11:50.265+0000] {task_command.py:388} INFO - Running <TaskInstance: airbyte_dynamic_connection.wait_for_airbyte_idle manual__2025-08-29T14:11:09+00:00 [running]> on host 966b32814b47
[2025-08-29T14:11:50.297+0000] {taskinstance.py:1509} INFO - Exporting the following env vars:
AIRFLOW_CTX_DAG_OWNER=***
AIRFLOW_CTX_DAG_ID=airbyte_dynamic_connection
AIRFLOW_CTX_TASK_ID=wait_for_airbyte_idle
AIRFLOW_CTX_EXECUTION_DATE=2025-08-29T14:11:09+00:00
AIRFLOW_CTX_TRY_NUMBER=1
AIRFLOW_CTX_DAG_RUN_ID=manual__2025-08-29T14:11:09+00:00
[2025-08-29T14:11:50.376+0000] {dynamic-airbyte-with-airflow.py:102} INFO - Job(s) still running for connection d2364efc-87ad-47f4-ada7-8e46469ae3d8
[2025-08-29T14:12:10.477+0000] {dynamic-airbyte-with-airflow.py:102} INFO - Job(s) still running for connection d2364efc-87ad-47f4-ada7-8e46469ae3d8
[2025-08-29T14:12:30.553+0000] {dynamic-airbyte-with-airflow.py:102} INFO - Job(s) still running for connection d2364efc-87ad-47f4-ada7-8e46469ae3d8
[2025-08-29T14:12:50.612+0000] {taskinstance.py:1768} ERROR - Task failed with exception
Traceback (most recent call last):
  File "/home/airflow/.local/lib/python3.7/site-packages/urllib3/connectionpool.py", line 710, in urlopen
    chunked=chunked,
  File "/home/airflow/.local/lib/python3.7/site-packages/urllib3/connectionpool.py", line 449, in _make_request
    six.raise_from(e, None)
  File "<string>", line 3, in raise_from
  File "/home/airflow/.local/lib/python3.7/site-packages/urllib3/connectionpool.py", line 444, in _make_request
    httplib_response = conn.getresponse()
  File "/usr/local/lib/python3.7/http/client.py", line 1373, in getresponse
    response.begin()
  File "/usr/local/lib/python3.7/http/client.py", line 319, in begin
    version, status, reason = self._read_status()
  File "/usr/local/lib/python3.7/http/client.py", line 288, in _read_status
    raise RemoteDisconnected("Remote end closed connection without"
http.client.RemoteDisconnected: Remote end closed connection without response

During handling of the above exception, another exception occurred:

Traceback (most recent call last):
  File "/home/airflow/.local/lib/python3.7/site-packages/requests/adapters.py", line 499, in send
    timeout=timeout,
  File "/home/airflow/.local/lib/python3.7/site-packages/urllib3/connectionpool.py", line 788, in urlopen
    method, url, error=e, _pool=self, _stacktrace=sys.exc_info()[2]
  File "/home/airflow/.local/lib/python3.7/site-packages/urllib3/util/retry.py", line 550, in increment
    raise six.reraise(type(error), error, _stacktrace)
  File "/home/airflow/.local/lib/python3.7/site-packages/urllib3/packages/six.py", line 769, in reraise
    raise value.with_traceback(tb)
  File "/home/airflow/.local/lib/python3.7/site-packages/urllib3/connectionpool.py", line 710, in urlopen
    chunked=chunked,
  File "/home/airflow/.local/lib/python3.7/site-packages/urllib3/connectionpool.py", line 449, in _make_request
    six.raise_from(e, None)
  File "<string>", line 3, in raise_from
  File "/home/airflow/.local/lib/python3.7/site-packages/urllib3/connectionpool.py", line 444, in _make_request
    httplib_response = conn.getresponse()
  File "/usr/local/lib/python3.7/http/client.py", line 1373, in getresponse
    response.begin()
  File "/usr/local/lib/python3.7/http/client.py", line 319, in begin
    version, status, reason = self._read_status()
  File "/usr/local/lib/python3.7/http/client.py", line 288, in _read_status
    raise RemoteDisconnected("Remote end closed connection without"
urllib3.exceptions.ProtocolError: ('Connection aborted.', RemoteDisconnected('Remote end closed connection without response'))

During handling of the above exception, another exception occurred:

Traceback (most recent call last):
  File "/home/airflow/.local/lib/python3.7/site-packages/airflow/sensors/base.py", line 199, in execute
    poke_return = self.poke(context)
  File "/opt/airflow/dags/dynamic-airbyte-with-airflow.py", line 90, in poke
    "configTypes": ["sync", "reset_connection"]
  File "/home/airflow/.local/lib/python3.7/site-packages/requests/api.py", line 115, in post
    return request("post", url, data=data, json=json, **kwargs)
  File "/home/airflow/.local/lib/python3.7/site-packages/requests/api.py", line 59, in request
    return session.request(method=method, url=url, **kwargs)
  File "/home/airflow/.local/lib/python3.7/site-packages/requests/sessions.py", line 587, in request
    resp = self.send(prep, **send_kwargs)
  File "/home/airflow/.local/lib/python3.7/site-packages/requests/sessions.py", line 701, in send
    r = adapter.send(request, **kwargs)
  File "/home/airflow/.local/lib/python3.7/site-packages/requests/adapters.py", line 547, in send
    raise ConnectionError(err, request=request)
requests.exceptions.ConnectionError: ('Connection aborted.', RemoteDisconnected('Remote end closed connection without response'))
[2025-08-29T14:12:50.629+0000] {taskinstance.py:1323} INFO - Marking task as FAILED. dag_id=airbyte_dynamic_connection, task_id=wait_for_airbyte_idle, execution_date=20250829T141109, start_date=20250829T141150, end_date=20250829T141250
[2025-08-29T14:12:50.647+0000] {standard_task_runner.py:105} ERROR - Failed to execute job 136 for task wait_for_airbyte_idle (('Connection aborted.', RemoteDisconnected('Remote end closed connection without response')); 18219)
[2025-08-29T14:12:50.662+0000] {local_task_job.py:208} INFO - Task exited with return code 1
[2025-08-29T14:12:50.686+0000] {taskinstance.py:2578} INFO - 0 downstream tasks scheduled from follow-on schedule check
